Workbook

Sheet Rules
B24: Game predictions
B25: Each game – points are awarded for the score when the game ends after 90 minutes(plus additional time where this is added to the 90 minutes). NOT after extra time in the knockout phases
B28: Category | D28: Definition | K28: Points
B29: Correct Result | D29: Predicting the exact score | K29: 5
B30: Correct Forecast | D30: Predicting a winning team or a draw but not exact score | K30: 2
B31: Incorrect Forecast | D31: Did not predict correct result or forecast | K31: 0
B34: Predictions before the tournament starts
B35: For each of the below categories 'Points' are awarded for each correct instance within the category
B37: Category | E37: Definition | K37: Points
B38: Group Stage Winners | E38: Predicting a Group Winner | K38: 3
B39: Finalists | E39: Predicting the 2 teams in the Final | K39: 5
B40: Overall Winner | E40: Predicting the Tournament Winner | K40: 5
B41: Highest Goal Scoring Team | E41: Predicting the Highest scoring Country (not including goals scored in penalty shootouts) | K41: 5
B43: Highest Goal Scorer | E43: Predicting the Highest goal scorer for selected Countries (not including goals scored in penalty shootouts) | K43: 3
B45: Total Goals Conceded by | E45: Predicting number of goals conceded by selected Countries (not including goals scored in penalty shootouts) | K45: 3

Sheet Extra_Details
B28: https://en.wikipedia.org/wiki/2026_FIFA_World_Cup
B30: Tie-breaking criteria for World Cup groups
B31: If two or more teams in the same group are equal on points after the completion of the group stage, the following criteria, in the order below, shall be applied to determine the ranking:
B32: Step one
B33: greatest number of points obtained in the group matches between the teams concerned
B34: superior goal difference resulting from the group matches between the teams concerned
B35: greatest number of goals scored in all group matches between the teams concerned
B36: If no decision can be made through this procedure, the criteria below shall apply as follows to the two or more teams still equal on points:
B37: Step two
B38: superior goal difference in all group matches
B39: greatest number of goals scored in all group matches
B40: highest team conduct score (players and team officials) relating to the number of yellow and red cards obtained
... B56: https://www.fifa.com/en/tournaments/mens/worldcup/canadamexicousa2026/articles/groups-how-teams-qualify-tie-breakers

Sheet Countries
A1: Country | B1: Group | C1: FIFA Ranking
A2: Mexico | B2: A | C2: 14 | E2: To check
A3: Korea Republic | B3: A | C3: 25 | E3: Group | F3: Count
A4: South Africa | B4: A | C4: 60 | E4: A | F4: =COUNTIF(B:B,E4) -> 4
A5: Czechia | B5: A | C5: 40 | E5: B | F5: =COUNTIF(B:B,E5) -> 4
A6: Switzerland | B6: B | C6: 19 | E6: C | F6: =COUNTIF(B:B,E6) -> 4
A7: Canada | B7: B | C7: 30 | E7: D | F7: =COUNTIF(B:B,E7) -> 4
A8: Qatar | B8: B | C8: 56 | E8: E | F8: =COUNTIF(B:B,E8) -> 4
A9: Bosnia and Herzegovina | B9: B | C9: 64 | E9: F | F9: =COUNTIF(B:B,E9) -> 4
A10: Brazil | B10: C | C10: 6 | E10: G | F10: =COUNTIF(B:B,E10) -> 4
A11: Morocco | B11: C | C11: 7 | E11: H | F11: =COUNTIF(B:B,E11) -> 4
A12: Scotland | B12: C | C12: 42 | E12: I | F12: =COUNTIF(B:B,E12) -> 4
A13: Haiti | B13: C | C13: 83 | E13: J | F13: =COUNTIF(B:B,E13) -> 4
A14: Türkiye | B14: D | C14: 22 | E14: K | F14: =COUNTIF(B:B,E14) -> 4
A15: Australia | B15: D | C15: 27 | E15: L | F15: =COUNTIF(B:B,E15) -> 4
A16: Paraguay | B16: D | C16: 41
A17: USA | B17: D | C17: 17
A18: Germany | B18: E | C18: 10
A19: Ecuador | B19: E | C19: 23
A20: Côte d'Ivoire | B20: E | C20: 33
A21: Curaçao | B21: E | C21: 82
A22: Netherlands | B22: F | C22: 8
A23: Japan | B23: F | C23: 18
A24: Sweden | B24: F | C24: 38
A25: Tunisia | B25: F | C25: 45
A26: Belgium | B26: G | C26: 9
A27: IR Iran | B27: G | C27: 20
... A49: Ghana | B49: L | C49: 73

Sheet Team_Sheet(s)
A1: Squad(s)
A2: England
A3: Shirt Number | B3: Player Name | C3: Position
A4: 1 | B4: Jordan Pickford | C4: Goalkeeper
A5: 13 | B5: Dean Henderson | C5: Goalkeeper
A6: 23 | B6: James Trafford | C6: Goalkeeper
A7: 5 | B7: John Stones | C7: Defender
A8: 6 | B8: Marc Guéhi | C8: Defender
A9: 2 | B9: Ezri Konsa | C9: Defender
A10: 15 | B10: Dan Burn | C10: Defender
A11: 26 | B11: Jarell Quansah | C11: Defender
A12: 24 | B12: Reece James | C12: Defender
A13: 12 | B13: Tino Livramento | C13: Defender
A14: 3 | B14: Nico O'Reilly | C14: Defender
A15: 25 | B15: Djed Spence | C15: Defender
... A29: 18 | B29: Anthony Gordon | C29: Forward

Sheet Fixtures
A1: GameID | B1: Date Time (GMT) | C1: Group/Stage | D1: Team1 | E1: Team2 | F1: Stadium
A2: 1 | B2: 46184.792 | C2: Group A | D2: Mexico | E2: South Africa | F2: Mexico City, Estadio Azteca
A3: 2 | B3: 46185.083 | C3: Group A | D3: Korea Republic | E3: Czechia | F3: Guadalajara, Estadio Akron
A4: 3 | B4: 46185.792 | C4: Group B | D4: Canada | E4: Bosnia and Herzegovina | F4: Toronto, BMO Field
A5: 4 | B5: 46186.042 | C5: Group D | D5: USA | E5: Paraguay | F5: Los Angeles, SoFi Stadium
A6: 5 | B6: 46186.792 | C6: Group B | D6: Qatar | E6: Switzerland | F6: San Francisco, Levi's Stadium
A7: 6 | B7: 46186.917 | C7: Group C | D7: Brazil | E7: Morocco | F7: New York/New Jersey, MetLife Stadium
A8: 7 | B8: 46187.042 | C8: Group C | D8: Haiti | E8: Scotland | F8: Boston, Gillette Stadium
A9: 8 | B9: 46187.167 | C9: Group D | D9: Australia | E9: Türkiye | F9: Vancouver, BC Place
A10: 9 | B10: 46187.708 | C10: Group E | D10: Germany | E10: Curaçao | F10: Houston, NRG Stadium
A11: 10 | B11: 46187.833 | C11: Group F | D11: Netherlands | E11: Japan | F11: Dallas, AT&T Stadium
A12: 11 | B12: 46187.958 | C12: Group E | D12: Côte d'Ivoire | E12: Ecuador | F12: Philadelphia, Lincoln Financial Field
A13: 12 | B13: 46188.083 | C13: Group F | D13: Sweden | E13: Tunisia | F13: Monterrey, Estadio BBVA
... A74: 73 | B74: 46201.792 | C74: Round of 32 | D74: Runner-up Group A | E74: Runner-up Group B | F74: Los Angeles, SoFi Stadium
A75: 74 | B75: 29/06/2026 20:30 | C75: Round of 32 | D75: Winner Group E | E75: 3rd Group A/B/C/D/F | F75: Boston, Gillette Stadium
A76: 75 | B76: 30/06/2026 01:00 | C76: Round of 32 | D76: Winner Group F | E76: Runner-up Group C | F76: Monterrey, Estadio BBVA
A77: 76 | B77: 29/06/2026 17:00 | C77: Round of 32 | D77: Winner Group C | E77: Runner-up Group F | F77: Houston, NRG Stadium
A78: 77 | B78: 30/06/2026 21:00 | C78: Round of 32 | D78: Winner Group I | E78: 3rd Group C/D/F/G/H | F78: New York/New Jersey, MetLife Stadium
A79: 78 | B79: 30/06/2026 17:00 | C79: Round of 32 | D79: Runner-up Group E | E79: Runner-up Group I | F79: Dallas, AT&T Stadium
A80: 79 | B80: 01/07/2026 01:00 | C80: Round of 32 | D80: Winner Group A | E80: 3rd Group C/E/F/H/I | F80: Mexico City, Estadio Azteca
A81: 80 | B81: 01/07/2026 16:00 | C81: Round of 32 | D81: Winner Group L | E81: 3rd Group E/H/I/J/K | F81: Atlanta, Mercedes-Benz Stadium
A82: 81 | B82: 02/07/2026 00:00 | C82: Round of 32 | D82: Winner Group D | E82: 3rd Group B/E/F/I/J | F82: San Francisco, Levi's Stadium
A83: 82 | B83: 01/07/2026 20:00 | C83: Round of 32 | D83: Winner Group G | E83: 3rd Group A/E/H/I/J | F83: Seattle, Lumen Field
A84: 83 | B84: 02/07/2026 23:00 | C84: Round of 32 | D84: Runner-up Group K | E84: Runner-up Group L | F84: Toronto, BMO Field
A85: 84 | B85: 02/07/2026 19:00 | C85: Round of 32 | D85: Winner Group H | E85: Runner-up Group J | F85: Los Angeles, SoFi Stadium
A86: 85 | B86: 03/07/2026 03:00 | C86: Round of 32 | D86: Winner Group B | E86: 3rd Group E/F/G/I/J | F86: Vancouver, BC Place
... A89: 88 | B89: 03/07/2026 18:00 | C89: Round of 32 | D89: Runner-up Group D | E89: Runner-up Group G | F89: Dallas, AT&T Stadium
A90: 89 | B90: 04/07/2026 21:00 | C90: Round of 16 | D90: {=_xlfn.IFS(OR(ISBLANK('Results'!E75),ISBLANK('Results'!F75)),"Winner 74",'Results'!E75>'Results'!F75,'Results'!D75,'Results'!E75<'Results'!F75,'Results'!G75,'Results'!E75='Results'!F75,'Results'!H75)} -> Winner 74 | E90: {=_xlfn.IFS(OR(ISBLANK('Results'!E78),ISBLANK('Results'!F78)),"Winner 77",'Results'!E78>'Results'!F78,'Results'!D78,'Results'!E78<'Results'!F78,'Results'!G78,'Results'!E78='Results'!F78,'Results'!H78)} -> Winner 77 | F90: Philadelphia, Lincoln Financial Field
A91: 90 | B91: 04/07/2026 17:00 | C91: Round of 16 | D91: {=_xlfn.IFS(OR(ISBLANK('Results'!E74),ISBLANK('Results'!F74)),"Winner 73",'Results'!E74>'Results'!F74,'Results'!D74,'Results'!E74<'Results'!F74,'Results'!G74,'Results'!E74='Results'!F74,'Results'!H74)} -> Winner 73 | E91: {=_xlfn.IFS(OR(ISBLANK('Results'!E76),ISBLANK('Results'!F76)),"Winner 75",'Results'!E76>'Results'!F76,'Results'!D76,'Results'!E76<'Results'!F76,'Results'!G76,'Results'!E76='Results'!F76,'Results'!H76)} -> Winner 75 | F91: Houston, NRG Stadium
A92: 91 | B92: 05/07/2026 20:00 | C92: Round of 16 | D92: {=_xlfn.IFS(OR(ISBLANK('Results'!E77),ISBLANK('Results'!F77)),"Winner 76",'Results'!E77>'Results'!F77,'Results'!D77,'Results'!E77<'Results'!F77,'Results'!G77,'Results'!E77='Results'!F77,'Results'!H77)} -> Winner 76 | E92: {=_xlfn.IFS(OR(ISBLANK('Results'!E79),ISBLANK('Results'!F79)),"Winner 78",'Results'!E79>'Results'!F79,'Results'!D79,'Results'!E79<'Results'!F79,'Results'!G79,'Results'!E79='Results'!F79,'Results'!H79)} -> Winner 78 | F92: New York/New Jersey, MetLife Stadium
A93: 92 | B93: 06/07/2026 00:00 | C93: Round of 16 | D93: {=_xlfn.IFS(OR(ISBLANK('Results'!E80),ISBLANK('Results'!F80)),"Winner 79",'Results'!E80>'Results'!F80,'Results'!D80,'Results'!E80<'Results'!F80,'Results'!G80,'Results'!E80='Results'!F80,'Results'!H80)} -> Winner 79 | E93: {=_xlfn.IFS(OR(ISBLANK('Results'!E81),ISBLANK('Results'!F81)),"Winner 80",'Results'!E81>'Results'!F81,'Results'!D81,'Results'!E81<'Results'!F81,'Results'!G81,'Results'!E81='Results'!F81,'Results'!H81)} -> Winner 80 | F93: Mexico City, Estadio Azteca
A94: 93 | B94: 46209.792 | C94: Round of 16 | D94: {=_xlfn.IFS(OR(ISBLANK('Results'!E84),ISBLANK('Results'!F84)),"Winner 83",'Results'!E84>'Results'!F84,'Results'!D84,'Results'!E84<'Results'!F84,'Results'!G84,'Results'!E84='Results'!F84,'Results'!H84)} -> Winner 83 | E94: {=_xlfn.IFS(OR(ISBLANK('Results'!E85),ISBLANK('Results'!F85)),"Winner 84",'Results'!E85>'Results'!F85,'Results'!D85,'Results'!E85<'Results'!F85,'Results'!G85,'Results'!E85='Results'!F85,'Results'!H85)} -> Winner 84 | F94: Dallas, AT&T Stadium
A95: 94 | B95: 07/07/2026 00:00 | C95: Round of 16 | D95: {=_xlfn.IFS(OR(ISBLANK('Results'!E82),ISBLANK('Results'!F82)),"Winner 81",'Results'!E82>'Results'!F82,'Results'!D82,'Results'!E82<'Results'!F82,'Results'!G82,'Results'!E82='Results'!F82,'Results'!H82)} -> Winner 81 | E95: {=_xlfn.IFS(OR(ISBLANK('Results'!E83),ISBLANK('Results'!F83)),"Winner 82",'Results'!E83>'Results'!F83,'Results'!D83,'Results'!E83<'Results'!F83,'Results'!G83,'Results'!E83='Results'!F83,'Results'!H83)} -> Winner 82 | F95: Seattle, Lumen Field
A96: 95 | B96: 07/07/2026 16:00 | C96: Round of 16 | D96: {=_xlfn.IFS(OR(ISBLANK('Results'!E87),ISBLANK('Results'!F87)),"Winner 86",'Results'!E87>'Results'!F87,'Results'!D87,'Results'!E87<'Results'!F87,'Results'!G87,'Results'!E87='Results'!F87,'Results'!H87)} -> Winner 86 | E96: {=_xlfn.IFS(OR(ISBLANK('Results'!E89),ISBLANK('Results'!F89)),"Winner 88",'Results'!E89>'Results'!F89,'Results'!D89,'Results'!E89<'Results'!F89,'Results'!G89,'Results'!E89='Results'!F89,'Results'!H89)} -> Winner 88 | F96: Atlanta, Mercedes-Benz Stadium
A97: 96 | B97: 07/07/2026 20:00 | C97: Round of 16 | D97: {=_xlfn.IFS(OR(ISBLANK('Results'!E86),ISBLANK('Results'!F86)),"Winner 85",'Results'!E86>'Results'!F86,'Results'!D86,'Results'!E86<'Results'!F86,'Results'!G86,'Results'!E86='Results'!F86,'Results'!H86)} -> Winner 85 | E97: {=_xlfn.IFS(OR(ISBLANK('Results'!E88),ISBLANK('Results'!F88)),"Winner 87",'Results'!E88>'Results'!F88,'Results'!D88,'Results'!E88<'Results'!F88,'Results'!G88,'Results'!E88='Results'!F88,'Results'!H88)} -> Winner 87 | F97: Vancouver, BC Place
A98: 97 | B98: 09/07/2026 20:00 | C98: Quarter-final | D98: {=_xlfn.IFS(OR(ISBLANK('Results'!E90),ISBLANK('Results'!F90)),"Winner 89",'Results'!E90>'Results'!F90,'Results'!D90,'Results'!E90<'Results'!F90,'Results'!G90,'Results'!E90='Results'!F90,'Results'!H90)} -> Winner 89 | E98: {=_xlfn.IFS(OR(ISBLANK('Results'!E91),ISBLANK('Results'!F91)),"Winner 90",'Results'!E91>'Results'!F91,'Results'!D91,'Results'!E91<'Results'!F91,'Results'!G91,'Results'!E91='Results'!F91,'Results'!H91)} -> Winner 90 | F98: Boston, Gillette Stadium
A99: 98 | B99: 46213.792 | C99: Quarter-final | D99: {=_xlfn.IFS(OR(ISBLANK('Results'!E94),ISBLANK('Results'!F94)),"Winner 93",'Results'!E94>'Results'!F94,'Results'!D94,'Results'!E94<'Results'!F94,'Results'!G94,'Results'!E94='Results'!F94,'Results'!H94)} -> Winner 93 | E99: {=_xlfn.IFS(OR(ISBLANK('Results'!E95),ISBLANK('Results'!F95)),"Winner 94",'Results'!E95>'Results'!F95,'Results'!D95,'Results'!E95<'Results'!F95,'Results'!G95,'Results'!E95='Results'!F95,'Results'!H95)} -> Winner 94 | F99: Los Angeles, SoFi Stadium
A100: 99 | B100: 11/07/2026 21:00 | C100: Quarter-final | D100: {=_xlfn.IFS(OR(ISBLANK('Results'!E92),ISBLANK('Results'!F92)),"Winner 91",'Results'!E92>'Results'!F92,'Results'!D92,'Results'!E92<'Results'!F92,'Results'!G92,'Results'!E92='Results'!F92,'Results'!H92)} -> Winner 91 | E100: {=_xlfn.IFS(OR(ISBLANK('Results'!E93),ISBLANK('Results'!F93)),"Winner 92",'Results'!E93>'Results'!F93,'Results'!D93,'Results'!E93<'Results'!F93,'Results'!G93,'Results'!E93='Results'!F93,'Results'!H93)} -> Winner 92 | F100: Miami, Hard Rock Stadium
A101: 100 | B101: 12/07/2026 01:00 | C101: Quarter-final | D101: {=_xlfn.IFS(OR(ISBLANK('Results'!E96),ISBLANK('Results'!F96)),"Winner 95",'Results'!E96>'Results'!F96,'Results'!D96,'Results'!E96<'Results'!F96,'Results'!G96,'Results'!E96='Results'!F96,'Results'!H96)} -> Winner 95 | E101: {=_xlfn.IFS(OR(ISBLANK('Results'!E97),ISBLANK('Results'!F97)),"Winner 96",'Results'!E97>'Results'!F97,'Results'!D97,'Results'!E97<'Results'!F97,'Results'!G97,'Results'!E97='Results'!F97,'Results'!H97)} -> Winner 96 | F101: Kansas City, Arrowhead Stadium
A102: 101 | B102: 46217.792 | C102: Semi-final | D102: {=_xlfn.IFS(OR(ISBLANK('Results'!E98),ISBLANK('Results'!F98)),"Winner 97",'Results'!E98>'Results'!F98,'Results'!D98,'Results'!E98<'Results'!F98,'Results'!G98,'Results'!E98='Results'!F98,'Results'!H98)} -> Winner 97 | E102: {=_xlfn.IFS(OR(ISBLANK('Results'!E99),ISBLANK('Results'!F99)),"Winner 98",'Results'!E99>'Results'!F99,'Results'!D99,'Results'!E99<'Results'!F99,'Results'!G99,'Results'!E99='Results'!F99,'Results'!H99)} -> Winner 98 | F102: Dallas, AT&T Stadium
...

Sheet Benchmark
A1: GameID | B1: Date Time (GMT) | C1: Group/Stage | D1: Team1 | E1: Score1 | F1: Score2 | G1: Team2 | H1: Stadium | I1: Blank | J1: Points
A2: =Fixtures!A2 -> 1 | B2: =Fixtures!B2 -> 46184.792 | C2: =Fixtures!C2 -> Group A | D2: =Fixtures!D2 -> Mexico | E2: =IF((_xlfn.XLOOKUP(Benchmark[[#This Row],[Team1]],Countries[Country],Countries[FIFA Ranking],,0)<(_xlfn.XLOOKUP(Benchmark[[#This Row],[Team2]],Countries[Country],Countries[FIFA Ranking],,0))),1,0) -> 1 | F2: =IF((_xlfn.XLOOKUP(Benchmark[[#This Row],[Team1]],Countries[Country],Countries[FIFA Ranking],,0)>(_xlfn.XLOOKUP(Benchmark[[#This Row],[Team2]],Countries[Country],Countries[FIFA Ranking],,0))),1,0) -> 0 | G2: =Fixtures!E2 -> South Africa | H2: =Fixtures!F2 -> Mexico City, Estadio Azteca | J2: {=_xlfn.IFS(OR(ISBLANK('Results'!E2),ISBLANK('Results'!F2)),0,OR(ISBLANK(E2),ISBLANK(F2)),0,AND(E2='Results'!E2,F2='Results'!F2),Rules!$K$29,_xlfn.XOR(AND(E2>F2,'Results'!E2>'Results'!F2),AND(E2<F2,'Results'!E2<'Results'!F2),AND(E2=F2,'Results'!E2='Results'!F2)),Rules!$K$30,TRUE,0)} -> 0 | L2: Other Predictions
A3: =Fixtures!A3 -> 2 | B3: =Fixtures!B3 -> 46185.083 | C3: =Fixtures!C3 -> Group A | D3: =Fixtures!D3 -> Korea Republic | E3: =IF((_xlfn.XLOOKUP(Benchmark[[#This Row],[Team1]],Countries[Country],Countries[FIFA Ranking],,0)<(_xlfn.XLOOKUP(Benchmark[[#This Row],[Team2]],Countries[Country],Countries[FIFA Ranking],,0))),1,0) -> 1 | F3: =IF((_xlfn.XLOOKUP(Benchmark[[#This Row],[Team1]],Countries[Country],Countries[FIFA Ranking],,0)>(_xlfn.XLOOKUP(Benchmark[[#This Row],[Team2]],Countries[Country],Countries[FIFA Ranking],,0))),1,0) -> 0 | G3: =Fixtures!E3 -> Czechia | H3: =Fixtures!F3 -> Guadalajara, Estadio Akron | J3: {=_xlfn.IFS(OR(ISBLANK('Results'!E3),ISBLANK('Results'!F3)),0,OR(ISBLANK(E3),ISBLANK(F3)),0,AND(E3='Results'!E3,F3='Results'!F3),Rules!$K$29,_xlfn.XOR(AND(E3>F3,'Results'!E3>'Results'!F3),AND(E3<F3,'Results'!E3<'Results'!F3),AND(E3=F3,'Results'!E3='Results'!F3)),Rules!$K$30,TRUE,0)} -> 0 | N3: Points
A4: =Fixtures!A4 -> 3 | B4: =Fixtures!B4 -> 46185.792 | C4: =Fixtures!C4 -> Group B | D4: =Fixtures!D4 -> Canada | E4: =IF((_xlfn.XLOOKUP(Benchmark[[#This Row],[Team1]],Countries[Country],Countries[FIFA Ranking],,0)<(_xlfn.XLOOKUP(Benchmark[[#This Row],[Team2]],Countries[Country],Countries[FIFA Ranking],,0))),1,0) -> 1 | F4: =IF((_xlfn.XLOOKUP(Benchmark[[#This Row],[Team1]],Countries[Country],Countries[FIFA Ranking],,0)>(_xlfn.XLOOKUP(Benchmark[[#This Row],[Team2]],Countries[Country],Countries[FIFA Ranking],,0))),1,0) -> 0 | G4: =Fixtures!E4 -> Bosnia and Herzegovina | H4: =Fixtures!F4 -> Toronto, BMO Field | J4: {=_xlfn.IFS(OR(ISBLANK('Results'!E4),ISBLANK('Results'!F4)),0,OR(ISBLANK(E4),ISBLANK(F4)),0,AND(E4='Results'!E4,F4='Results'!F4),Rules!$K$29,_xlfn.XOR(AND(E4>F4,'Results'!E4>'Results'!F4),AND(E4<F4,'Results'!E4<'Results'!F4),AND(E4=F4,'Results'!E4='Results'!F4)),Rules!$K$30,TRUE,0)} -> 0 | L4: Group Stage Winners
A5: =Fixtures!A5 -> 4 | B5: =Fixtures!B5 -> 46186.042 | C5: =Fixtures!C5 -> Group D | D5: =Fixtures!D5 -> USA | E5: =IF((_xlfn.XLOOKUP(Benchmark[[#This Row],[Team1]],Countries[Country],Countries[FIFA Ranking],,0)<(_xlfn.XLOOKUP(Benchmark[[#This Row],[Team2]],Countries[Country],Countries[FIFA Ranking],,0))),1,0) -> 1 | F5: =IF((_xlfn.XLOOKUP(Benchmark[[#This Row],[Team1]],Countries[Country],Countries[FIFA Ranking],,0)>(_xlfn.XLOOKUP(Benchmark[[#This Row],[Team2]],Countries[Country],Countries[FIFA Ranking],,0))),1,0) -> 0 | G5: =Fixtures!E5 -> Paraguay | H5: =Fixtures!F5 -> Los Angeles, SoFi Stadium | J5: {=_xlfn.IFS(OR(ISBLANK('Results'!E5),ISBLANK('Results'!F5)),0,OR(ISBLANK(E5),ISBLANK(F5)),0,AND(E5='Results'!E5,F5='Results'!F5),Rules!$K$29,_xlfn.XOR(AND(E5>F5,'Results'!E5>'Results'!F5),AND(E5<F5,'Results'!E5<'Results'!F5),AND(E5=F5,'Results'!E5='Results'!F5)),Rules!$K$30,TRUE,0)} -> 0 | L5: Group | M5: Winner
A6: =Fixtures!A6 -> 5 | B6: =Fixtures!B6 -> 46186.792 | C6: =Fixtures!C6 -> Group B | D6: =Fixtures!D6 -> Qatar | E6: =IF((_xlfn.XLOOKUP(Benchmark[[#This Row],[Team1]],Countries[Country],Countries[FIFA Ranking],,0)<(_xlfn.XLOOKUP(Benchmark[[#This Row],[Team2]],Countries[Country],Countries[FIFA Ranking],,0))),1,0) -> 0 | F6: =IF((_xlfn.XLOOKUP(Benchmark[[#This Row],[Team1]],Countries[Country],Countries[FIFA Ranking],,0)>(_xlfn.XLOOKUP(Benchmark[[#This Row],[Team2]],Countries[Country],Countries[FIFA Ranking],,0))),1,0) -> 1 | G6: =Fixtures!E6 -> Switzerland | H6: =Fixtures!F6 -> San Francisco, Levi's Stadium | J6: {=_xlfn.IFS(OR(ISBLANK('Results'!E6),ISBLANK('Results'!F6)),0,OR(ISBLANK(E6),ISBLANK(F6)),0,AND(E6='Results'!E6,F6='Results'!F6),Rules!$K$29,_xlfn.XOR(AND(E6>F6,'Results'!E6>'Results'!F6),AND(E6<F6,'Results'!E6<'Results'!F6),AND(E6=F6,'Results'!E6='Results'!F6)),Rules!$K$30,TRUE,0)} -> 0 | L6: A | M6: {=INDEX(Countries[Country],MATCH(_xlfn.MINIFS(Countries[FIFA Ranking],Countries[Group],L6),IF(Countries[Group]=L6,Countries[FIFA Ranking]),0))} -> Mexico | N6: {=_xlfn.IFS(OR(ISBLANK(M6),ISBLANK('Results'!K6)),0,M6='Results'!K6,Rules!$K$38,TRUE,0)} -> 0
A7: =Fixtures!A7 -> 6 | B7: =Fixtures!B7 -> 46186.917 | C7: =Fixtures!C7 -> Group C | D7: =Fixtures!D7 -> Brazil | E7: =IF((_xlfn.XLOOKUP(Benchmark[[#This Row],[Team1]],Countries[Country],Countries[FIFA Ranking],,0)<(_xlfn.XLOOKUP(Benchmark[[#This Row],[Team2]],Countries[Country],Countries[FIFA Ranking],,0))),1,0) -> 1 | F7: =IF((_xlfn.XLOOKUP(Benchmark[[#This Row],[Team1]],Countries[Country],Countries[FIFA Ranking],,0)>(_xlfn.XLOOKUP(Benchmark[[#This Row],[Team2]],Countries[Country],Countries[FIFA Ranking],,0))),1,0) -> 0 | G7: =Fixtures!E7 -> Morocco | H7: =Fixtures!F7 -> New York/New Jersey, MetLife Stadium | J7: {=_xlfn.IFS(OR(ISBLANK('Results'!E7),ISBLANK('Results'!F7)),0,OR(ISBLANK(E7),ISBLANK(F7)),0,AND(E7='Results'!E7,F7='Results'!F7),Rules!$K$29,_xlfn.XOR(AND(E7>F7,'Results'!E7>'Results'!F7),AND(E7<F7,'Results'!E7<'Results'!F7),AND(E7=F7,'Results'!E7='Results'!F7)),Rules!$K$30,TRUE,0)} -> 0 | L7: B | M7: {=INDEX(Countries[Country],MATCH(_xlfn.MINIFS(Countries[FIFA Ranking],Countries[Group],L7),IF(Countries[Group]=L7,Countries[FIFA Ranking]),0))} -> Switzerland | N7: {=_xlfn.IFS(OR(ISBLANK(M7),ISBLANK('Results'!K7)),0,M7='Results'!K7,Rules!$K$38,TRUE,0)} -> 0
A8: =Fixtures!A8 -> 7 | B8: =Fixtures!B8 -> 46187.042 | C8: =Fixtures!C8 -> Group C | D8: =Fixtures!D8 -> Haiti | E8: =IF((_xlfn.XLOOKUP(Benchmark[[#This Row],[Team1]],Countries[Country],Countries[FIFA Ranking],,0)<(_xlfn.XLOOKUP(Benchmark[[#This Row],[Team2]],Countries[Country],Countries[FIFA Ranking],,0))),1,0) -> 0 | F8: =IF((_xlfn.XLOOKUP(Benchmark[[#This Row],[Team1]],Countries[Country],Countries[FIFA Ranking],,0)>(_xlfn.XLOOKUP(Benchmark[[#This Row],[Team2]],Countries[Country],Countries[FIFA Ranking],,0))),1,0) -> 1 | G8: =Fixtures!E8 -> Scotland | H8: =Fixtures!F8 -> Boston, Gillette Stadium | J8: {=_xlfn.IFS(OR(ISBLANK('Results'!E8),ISBLANK('Results'!F8)),0,OR(ISBLANK(E8),ISBLANK(F8)),0,AND(E8='Results'!E8,F8='Results'!F8),Rules!$K$29,_xlfn.XOR(AND(E8>F8,'Results'!E8>'Results'!F8),AND(E8<F8,'Results'!E8<'Results'!F8),AND(E8=F8,'Results'!E8='Results'!F8)),Rules!$K$30,TRUE,0)} -> 0 | L8: C | M8: {=INDEX(Countries[Country],MATCH(_xlfn.MINIFS(Countries[FIFA Ranking],Countries[Group],L8),IF(Countries[Group]=L8,Countries[FIFA Ranking]),0))} -> Brazil | N8: {=_xlfn.IFS(OR(ISBLANK(M8),ISBLANK('Results'!K8)),0,M8='Results'!K8,Rules!$K$38,TRUE,0)} -> 0
A9: =Fixtures!A9 -> 8 | B9: =Fixtures!B9 -> 46187.167 | C9: =Fixtures!C9 -> Group D | D9: =Fixtures!D9 -> Australia | E9: =IF((_xlfn.XLOOKUP(Benchmark[[#This Row],[Team1]],Countries[Country],Countries[FIFA Ranking],,0)<(_xlfn.XLOOKUP(Benchmark[[#This Row],[Team2]],Countries[Country],Countries[FIFA Ranking],,0))),1,0) -> 0 | F9: =IF((_xlfn.XLOOKUP(Benchmark[[#This Row],[Team1]],Countries[Country],Countries[FIFA Ranking],,0)>(_xlfn.XLOOKUP(Benchmark[[#This Row],[Team2]],Countries[Country],Countries[FIFA Ranking],,0))),1,0) -> 1 | G9: =Fixtures!E9 -> Türkiye | H9: =Fixtures!F9 -> Vancouver, BC Place | J9: {=_xlfn.IFS(OR(ISBLANK('Results'!E9),ISBLANK('Results'!F9)),0,OR(ISBLANK(E9),ISBLANK(F9)),0,AND(E9='Results'!E9,F9='Results'!F9),Rules!$K$29,_xlfn.XOR(AND(E9>F9,'Results'!E9>'Results'!F9),AND(E9<F9,'Results'!E9<'Results'!F9),AND(E9=F9,'Results'!E9='Results'!F9)),Rules!$K$30,TRUE,0)} -> 0 | L9: D | M9: {=INDEX(Countries[Country],MATCH(_xlfn.MINIFS(Countries[FIFA Ranking],Countries[Group],L9),IF(Countries[Group]=L9,Countries[FIFA Ranking]),0))} -> USA | N9: {=_xlfn.IFS(OR(ISBLANK(M9),ISBLANK('Results'!K9)),0,M9='Results'!K9,Rules!$K$38,TRUE,0)} -> 0
A10: =Fixtures!A10 -> 9 | B10: =Fixtures!B10 -> 46187.708 | C10: =Fixtures!C10 -> Group E | D10: =Fixtures!D10 -> Germany | E10: =IF((_xlfn.XLOOKUP(Benchmark[[#This Row],[Team1]],Countries[Country],Countries[FIFA Ranking],,0)<(_xlfn.XLOOKUP(Benchmark[[#This Row],[Team2]],Countries[Country],Countries[FIFA Ranking],,0))),1,0) -> 1 | F10: =IF((_xlfn.XLOOKUP(Benchmark[[#This Row],[Team1]],Countries[Country],Countries[FIFA Ranking],,0)>(_xlfn.XLOOKUP(Benchmark[[#This Row],[Team2]],Countries[Country],Countries[FIFA Ranking],,0))),1,0) -> 0 | G10: =Fixtures!E10 -> Curaçao | H10: =Fixtures!F10 -> Houston, NRG Stadium | J10: {=_xlfn.IFS(OR(ISBLANK('Results'!E10),ISBLANK('Results'!F10)),0,OR(ISBLANK(E10),ISBLANK(F10)),0,AND(E10='Results'!E10,F10='Results'!F10),Rules!$K$29,_xlfn.XOR(AND(E10>F10,'Results'!E10>'Results'!F10),AND(E10<F10,'Results'!E10<'Results'!F10),AND(E10=F10,'Results'!E10='Results'!F10)),Rules!$K$30,TRUE,0)} -> 0 | L10: E | M10: {=INDEX(Countries[Country],MATCH(_xlfn.MINIFS(Countries[FIFA Ranking],Countries[Group],L10),IF(Countries[Group]=L10,Countries[FIFA Ranking]),0))} -> Germany | N10: {=_xlfn.IFS(OR(ISBLANK(M10),ISBLANK('Results'!K10)),0,M10='Results'!K10,Rules!$K$38,TRUE,0)} -> 0
A11: =Fixtures!A11 -> 10 | B11: =Fixtures!B11 -> 46187.833 | C11: =Fixtures!C11 -> Group F | D11: =Fixtures!D11 -> Netherlands | E11: =IF((_xlfn.XLOOKUP(Benchmark[[#This Row],[Team1]],Countries[Country],Countries[FIFA Ranking],,0)<(_xlfn.XLOOKUP(Benchmark[[#This Row],[Team2]],Countries[Country],Countries[FIFA Ranking],,0))),1,0) -> 1 | F11: =IF((_xlfn.XLOOKUP(Benchmark[[#This Row],[Team1]],Countries[Country],Countries[FIFA Ranking],,0)>(_xlfn.XLOOKUP(Benchmark[[#This Row],[Team2]],Countries[Country],Countries[FIFA Ranking],,0))),1,0) -> 0 | G11: =Fixtures!E11 -> Japan | H11: =Fixtures!F11 -> Dallas, AT&T Stadium | J11: {=_xlfn.IFS(OR(ISBLANK('Results'!E11),ISBLANK('Results'!F11)),0,OR(ISBLANK(E11),ISBLANK(F11)),0,AND(E11='Results'!E11,F11='Results'!F11),Rules!$K$29,_xlfn.XOR(AND(E11>F11,'Results'!E11>'Results'!F11),AND(E11<F11,'Results'!E11<'Results'!F11),AND(E11=F11,'Results'!E11='Results'!F11)),Rules!$K$30,TRUE,0)} -> 0 | L11: F | M11: {=INDEX(Countries[Country],MATCH(_xlfn.MINIFS(Countries[FIFA Ranking],Countries[Group],L11),IF(Countries[Group]=L11,Countries[FIFA Ranking]),0))} -> Netherlands | N11: {=_xlfn.IFS(OR(ISBLANK(M11),ISBLANK('Results'!K11)),0,M11='Results'!K11,Rules!$K$38,TRUE,0)} -> 0
A12: =Fixtures!A12 -> 11 | B12: =Fixtures!B12 -> 46187.958 | C12: =Fixtures!C12 -> Group E | D12: =Fixtures!D12 -> Côte d'Ivoire | E12: =IF((_xlfn.XLOOKUP(Benchmark[[#This Row],[Team1]],Countries[Country],Countries[FIFA Ranking],,0)<(_xlfn.XLOOKUP(Benchmark[[#This Row],[Team2]],Countries[Country],Countries[FIFA Ranking],,0))),1,0) -> 0 | F12: =IF((_xlfn.XLOOKUP(Benchmark[[#This Row],[Team1]],Countries[Country],Countries[FIFA Ranking],,0)>(_xlfn.XLOOKUP(Benchmark[[#This Row],[Team2]],Countries[Country],Countries[FIFA Ranking],,0))),1,0) -> 1 | G12: =Fixtures!E12 -> Ecuador | H12: =Fixtures!F12 -> Philadelphia, Lincoln Financial Field | J12: {=_xlfn.IFS(OR(ISBLANK('Results'!E12),ISBLANK('Results'!F12)),0,OR(ISBLANK(E12),ISBLANK(F12)),0,AND(E12='Results'!E12,F12='Results'!F12),Rules!$K$29,_xlfn.XOR(AND(E12>F12,'Results'!E12>'Results'!F12),AND(E12<F12,'Results'!E12<'Results'!F12),AND(E12=F12,'Results'!E12='Results'!F12)),Rules!$K$30,TRUE,0)} -> 0 | L12: G | M12: {=INDEX(Countries[Country],MATCH(_xlfn.MINIFS(Countries[FIFA Ranking],Countries[Group],L12),IF(Countries[Group]=L12,Countries[FIFA Ranking]),0))} -> Belgium | N12: {=_xlfn.IFS(OR(ISBLANK(M12),ISBLANK('Results'!K12)),0,M12='Results'!K12,Rules!$K$38,TRUE,0)} -> 0
A13: =Fixtures!A13 -> 12 | B13: =Fixtures!B13 -> 46188.083 | C13: =Fixtures!C13 -> Group F | D13: =Fixtures!D13 -> Sweden | E13: =IF((_xlfn.XLOOKUP(Benchmark[[#This Row],[Team1]],Countries[Country],Countries[FIFA Ranking],,0)<(_xlfn.XLOOKUP(Benchmark[[#This Row],[Team2]],Countries[Country],Countries[FIFA Ranking],,0))),1,0) -> 1 | F13: =IF((_xlfn.XLOOKUP(Benchmark[[#This Row],[Team1]],Countries[Country],Countries[FIFA Ranking],,0)>(_xlfn.XLOOKUP(Benchmark[[#This Row],[Team2]],Countries[Country],Countries[FIFA Ranking],,0))),1,0) -> 0 | G13: =Fixtures!E13 -> Tunisia | H13: =Fixtures!F13 -> Monterrey, Estadio BBVA | J13: {=_xlfn.IFS(OR(ISBLANK('Results'!E13),ISBLANK('Results'!F13)),0,OR(ISBLANK(E13),ISBLANK(F13)),0,AND(E13='Results'!E13,F13='Results'!F13),Rules!$K$29,_xlfn.XOR(AND(E13>F13,'Results'!E13>'Results'!F13),AND(E13<F13,'Results'!E13<'Results'!F13),AND(E13=F13,'Results'!E13='Results'!F13)),Rules!$K$30,TRUE,0)} -> 0 | L13: H | M13: {=INDEX(Countries[Country],MATCH(_xlfn.MINIFS(Countries[FIFA Ranking],Countries[Group],L13),IF(Countries[Group]=L13,Countries[FIFA Ranking]),0))} -> Spain | N13: {=_xlfn.IFS(OR(ISBLANK(M13),ISBLANK('Results'!K13)),0,M13='Results'!K13,Rules!$K$38,TRUE,0)} -> 0
A14: =Fixtures!A14 -> 13 | B14: =Fixtures!B14 -> 46188.667 | C14: =Fixtures!C14 -> Group H | D14: =Fixtures!D14 -> Spain | E14: =IF((_xlfn.XLOOKUP(Benchmark[[#This Row],[Team1]],Countries[Country],Countries[FIFA Ranking],,0)<(_xlfn.XLOOKUP(Benchmark[[#This Row],[Team2]],Countries[Country],Countries[FIFA Ranking],,0))),1,0) -> 1 | F14: =IF((_xlfn.XLOOKUP(Benchmark[[#This Row],[Team1]],Countries[Country],Countries[FIFA Ranking],,0)>(_xlfn.XLOOKUP(Benchmark[[#This Row],[Team2]],Countries[Country],Countries[FIFA Ranking],,0))),1,0) -> 0 | G14: =Fixtures!E14 -> Cabo Verde | H14: =Fixtures!F14 -> Atlanta, Mercedes-Benz Stadium | J14: {=_xlfn.IFS(OR(ISBLANK('Results'!E14),ISBLANK('Results'!F14)),0,OR(ISBLANK(E14),ISBLANK(F14)),0,AND(E14='Results'!E14,F14='Results'!F14),Rules!$K$29,_xlfn.XOR(AND(E14>F14,'Results'!E14>'Results'!F14),AND(E14<F14,'Results'!E14<'Results'!F14),AND(E14=F14,'Results'!E14='Results'!F14)),Rules!$K$30,TRUE,0)} -> 0 | L14: I | M14: {=INDEX(Countries[Country],MATCH(_xlfn.MINIFS(Countries[FIFA Ranking],Countries[Group],L14),IF(Countries[Group]=L14,Countries[FIFA Ranking]),0))} -> France | N14: {=_xlfn.IFS(OR(ISBLANK(M14),ISBLANK('Results'!K14)),0,M14='Results'!K14,Rules!$K$38,TRUE,0)} -> 0
A15: =Fixtures!A15 -> 14 | B15: =Fixtures!B15 -> 46188.792 | C15: =Fixtures!C15 -> Group G | D15: =Fixtures!D15 -> Belgium | E15: =IF((_xlfn.XLOOKUP(Benchmark[[#This Row],[Team1]],Countries[Country],Countries[FIFA Ranking],,0)<(_xlfn.XLOOKUP(Benchmark[[#This Row],[Team2]],Countries[Country],Countries[FIFA Ranking],,0))),1,0) -> 1 | F15: =IF((_xlfn.XLOOKUP(Benchmark[[#This Row],[Team1]],Countries[Country],Countries[FIFA Ranking],,0)>(_xlfn.XLOOKUP(Benchmark[[#This Row],[Team2]],Countries[Country],Countries[FIFA Ranking],,0))),1,0) -> 0 | G15: =Fixtures!E15 -> Egypt | H15: =Fixtures!F15 -> Seattle, Lumen Field | J15: {=_xlfn.IFS(OR(ISBLANK('Results'!E15),ISBLANK('Results'!F15)),0,OR(ISBLANK(E15),ISBLANK(F15)),0,AND(E15='Results'!E15,F15='Results'!F15),Rules!$K$29,_xlfn.XOR(AND(E15>F15,'Results'!E15>'Results'!F15),AND(E15<F15,'Results'!E15<'Results'!F15),AND(E15=F15,'Results'!E15='Results'!F15)),Rules!$K$30,TRUE,0)} -> 0 | L15: J | M15: {=INDEX(Countries[Country],MATCH(_xlfn.MINIFS(Countries[FIFA Ranking],Countries[Group],L15),IF(Countries[Group]=L15,Countries[FIFA Ranking]),0))} -> Argentina | N15: {=_xlfn.IFS(OR(ISBLANK(M15),ISBLANK('Results'!K15)),0,M15='Results'!K15,Rules!$K$38,TRUE,0)} -> 0
A16: =Fixtures!A16 -> 15 | B16: =Fixtures!B16 -> 46188.917 | C16: =Fixtures!C16 -> Group H | D16: =Fixtures!D16 -> Saudi Arabia | E16: =IF((_xlfn.XLOOKUP(Benchmark[[#This Row],[Team1]],Countries[Country],Countries[FIFA Ranking],,0)<(_xlfn.XLOOKUP(Benchmark[[#This Row],[Team2]],Countries[Country],Countries[FIFA Ranking],,0))),1,0) -> 0 | F16: =IF((_xlfn.XLOOKUP(Benchmark[[#This Row],[Team1]],Countries[Country],Countries[FIFA Ranking],,0)>(_xlfn.XLOOKUP(Benchmark[[#This Row],[Team2]],Countries[Country],Countries[FIFA Ranking],,0))),1,0) -> 1 | G16: =Fixtures!E16 -> Uruguay | H16: =Fixtures!F16 -> Miami, Hard Rock Stadium | J16: {=_xlfn.IFS(OR(ISBLANK('Results'!E16),ISBLANK('Results'!F16)),0,OR(ISBLANK(E16),ISBLANK(F16)),0,AND(E16='Results'!E16,F16='Results'!F16),Rules!$K$29,_xlfn.XOR(AND(E16>F16,'Results'!E16>'Results'!F16),AND(E16<F16,'Results'!E16<'Results'!F16),AND(E16=F16,'Results'!E16='Results'!F16)),Rules!$K$30,TRUE,0)} -> 0 | L16: K | M16: {=INDEX(Countries[Country],MATCH(_xlfn.MINIFS(Countries[FIFA Ranking],Countries[Group],L16),IF(Countries[Group]=L16,Countries[FIFA Ranking]),0))} -> Portugal | N16: {=_xlfn.IFS(OR(ISBLANK(M16),ISBLANK('Results'!K16)),0,M16='Results'!K16,Rules!$K$38,TRUE,0)} -> 0
A17: =Fixtures!A17 -> 16 | B17: =Fixtures!B17 -> 46189.042 | C17: =Fixtures!C17 -> Group G | D17: =Fixtures!D17 -> IR Iran | E17: =IF((_xlfn.XLOOKUP(Benchmark[[#This Row],[Team1]],Countries[Country],Countries[FIFA Ranking],,0)<(_xlfn.XLOOKUP(Benchmark[[#This Row],[Team2]],Countries[Country],Countries[FIFA Ranking],,0))),1,0) -> 1 | F17: =IF((_xlfn.XLOOKUP(Benchmark[[#This Row],[Team1]],Countries[Country],Countries[FIFA Ranking],,0)>(_xlfn.XLOOKUP(Benchmark[[#This Row],[Team2]],Countries[Country],Countries[FIFA Ranking],,0))),1,0) -> 0 | G17: =Fixtures!E17 -> New Zealand | H17: =Fixtures!F17 -> Los Angeles, SoFi Stadium | J17: {=_xlfn.IFS(OR(ISBLANK('Results'!E17),ISBLANK('Results'!F17)),0,OR(ISBLANK(E17),ISBLANK(F17)),0,AND(E17='Results'!E17,F17='Results'!F17),Rules!$K$29,_xlfn.XOR(AND(E17>F17,'Results'!E17>'Results'!F17),AND(E17<F17,'Results'!E17<'Results'!F17),AND(E17=F17,'Results'!E17='Results'!F17)),Rules!$K$30,TRUE,0)} -> 0 | L17: L | M17: {=INDEX(Countries[Country],MATCH(_xlfn.MINIFS(Countries[FIFA Ranking],Countries[Group],L17),IF(Countries[Group]=L17,Countries[FIFA Ranking]),0))} -> England | N17: {=_xlfn.IFS(OR(ISBLANK(M17),ISBLANK('Results'!K17)),0,M17='Results'!K17,Rules!$K$38,TRUE,0)} -> 0
A18: =Fixtures!A18 -> 17 | B18: =Fixtures!B18 -> 46189.792 | C18: =Fixtures!C18 -> Group I | D18: =Fixtures!D18 -> France | E18: =IF((_xlfn.XLOOKUP(Benchmark[[#This Row],[Team1]],Countries[Country],Countries[FIFA Ranking],,0)<(_xlfn.XLOOKUP(Benchmark[[#This Row],[Team2]],Countries[Country],Countries[FIFA Ranking],,0))),1,0) -> 1 | F18: =IF((_xlfn.XLOOKUP(Benchmark[[#This Row],[Team1]],Countries[Country],Countries[FIFA Ranking],,0)>(_xlfn.XLOOKUP(Benchmark[[#This Row],[Team2]],Countries[Country],Countries[FIFA Ranking],,0))),1,0) -> 0 | G18: =Fixtures!E18 -> Senegal | H18: =Fixtures!F18 -> New York/New Jersey, MetLife Stadium | J18: {=_xlfn.IFS(OR(ISBLANK('Results'!E18),ISBLANK('Results'!F18)),0,OR(ISBLANK(E18),ISBLANK(F18)),0,AND(E18='Results'!E18,F18='Results'!F18),Rules!$K$29,_xlfn.XOR(AND(E18>F18,'Results'!E18>'Results'!F18),AND(E18<F18,'Results'!E18<'Results'!F18),AND(E18=F18,'Results'!E18='Results'!F18)),Rules!$K$30,TRUE,0)} -> 0
A19: =Fixtures!A19 -> 18 | B19: =Fixtures!B19 -> 46189.917 | C19: =Fixtures!C19 -> Group I | D19: =Fixtures!D19 -> Iraq | E19: =IF((_xlfn.XLOOKUP(Benchmark[[#This Row],[Team1]],Countries[Country],Countries[FIFA Ranking],,0)<(_xlfn.XLOOKUP(Benchmark[[#This Row],[Team2]],Countries[Country],Countries[FIFA Ranking],,0))),1,0) -> 0 | F19: =IF((_xlfn.XLOOKUP(Benchmark[[#This Row],[Team1]],Countries[Country],Countries[FIFA Ranking],,0)>(_xlfn.XLOOKUP(Benchmark[[#This Row],[Team2]],Countries[Country],Countries[FIFA Ranking],,0))),1,0) -> 1 | G19: =Fixtures!E19 -> Norway | H19: =Fixtures!F19 -> Boston, Gillette Stadium | J19: {=_xlfn.IFS(OR(ISBLANK('Results'!E19),ISBLANK('Results'!F19)),0,OR(ISBLANK(E19),ISBLANK(F19)),0,AND(E19='Results'!E19,F19='Results'!F19),Rules!$K$29,_xlfn.XOR(AND(E19>F19,'Results'!E19>'Results'!F19),AND(E19<F19,'Results'!E19<'Results'!F19),AND(E19=F19,'Results'!E19='Results'!F19)),Rules!$K$30,TRUE,0)} -> 0 | L19: Finalists
A20: =Fixtures!A20 -> 19 | B20: =Fixtures!B20 -> 46190.042 | C20: =Fixtures!C20 -> Group J | D20: =Fixtures!D20 -> Argentina | E20: =IF((_xlfn.XLOOKUP(Benchmark[[#This Row],[Team1]],Countries[Country],Countries[FIFA Ranking],,0)<(_xlfn.XLOOKUP(Benchmark[[#This Row],[Team2]],Countries[Country],Countries[FIFA Ranking],,0))),1,0) -> 1 | F20: =IF((_xlfn.XLOOKUP(Benchmark[[#This Row],[Team1]],Countries[Country],Countries[FIFA Ranking],,0)>(_xlfn.XLOOKUP(Benchmark[[#This Row],[Team2]],Countries[Country],Countries[FIFA Ranking],,0))),1,0) -> 0 | G20: =Fixtures!E20 -> Algeria | H20: =Fixtures!F20 -> Kansas City, Arrowhead Stadium | J20: {=_xlfn.IFS(OR(ISBLANK('Results'!E20),ISBLANK('Results'!F20)),0,OR(ISBLANK(E20),ISBLANK(F20)),0,AND(E20='Results'!E20,F20='Results'!F20),Rules!$K$29,_xlfn.XOR(AND(E20>F20,'Results'!E20>'Results'!F20),AND(E20<F20,'Results'!E20<'Results'!F20),AND(E20=F20,'Results'!E20='Results'!F20)),Rules!$K$30,TRUE,0)} -> 0 | L20: Team 1 | M20: {=INDEX(M6:M17,MATCH(MIN(INDEX(_xlfn.XLOOKUP(M6:M17,Countries[Country],Countries[FIFA Ranking]),)),INDEX(_xlfn.XLOOKUP(M6:M17,Countries[Country],Countries[FIFA Ranking]),),0))} -> Argentina | N20: {=_xlfn.IFS(OR(ISBLANK(M20),ISBLANK('Results'!K20)),0,M20='Results'!K20,Rules!$K$39,TRUE,0)} -> 0
A21: =Fixtures!A21 -> 20 | B21: =Fixtures!B21 -> 46190.167 | C21: =Fixtures!C21 -> Group J | D21: =Fixtures!D21 -> Austria | E21: =IF((_xlfn.XLOOKUP(Benchmark[[#This Row],[Team1]],Countries[Country],Countries[FIFA Ranking],,0)<(_xlfn.XLOOKUP(Benchmark[[#This Row],[Team2]],Countries[Country],Countries[FIFA Ranking],,0))),1,0) -> 1 | F21: =IF((_xlfn.XLOOKUP(Benchmark[[#This Row],[Team1]],Countries[Country],Countries[FIFA Ranking],,0)>(_xlfn.XLOOKUP(Benchmark[[#This Row],[Team2]],Countries[Country],Countries[FIFA Ranking],,0))),1,0) -> 0 | G21: =Fixtures!E21 -> Jordan | H21: =Fixtures!F21 -> San Francisco, Levi's Stadium | J21: {=_xlfn.IFS(OR(ISBLANK('Results'!E21),ISBLANK('Results'!F21)),0,OR(ISBLANK(E21),ISBLANK(F21)),0,AND(E21='Results'!E21,F21='Results'!F21),Rules!$K$29,_xlfn.XOR(AND(E21>F21,'Results'!E21>'Results'!F21),AND(E21<F21,'Results'!E21<'Results'!F21),AND(E21=F21,'Results'!E21='Results'!F21)),Rules!$K$30,TRUE,0)} -> 0 | L21: Team 2 | M21: {=INDEX(M6:M17,MATCH(SMALL(INDEX(_xlfn.XLOOKUP(M6:M17,Countries[Country],Countries[FIFA Ranking]),),2),INDEX(_xlfn.XLOOKUP(M6:M17,Countries[Country],Countries[FIFA Ranking]),),0))} -> Spain | N21: {=_xlfn.IFS(OR(ISBLANK(M21),ISBLANK('Results'!K21)),0,M21='Results'!K21,Rules!$K$39,TRUE,0)} -> 0
A22: =Fixtures!A22 -> 21 | B22: =Fixtures!B22 -> 46190.708 | C22: =Fixtures!C22 -> Group K | D22: =Fixtures!D22 -> Portugal | E22: =IF((_xlfn.XLOOKUP(Benchmark[[#This Row],[Team1]],Countries[Country],Countries[FIFA Ranking],,0)<(_xlfn.XLOOKUP(Benchmark[[#This Row],[Team2]],Countries[Country],Countries[FIFA Ranking],,0))),1,0) -> 1 | F22: =IF((_xlfn.XLOOKUP(Benchmark[[#This Row],[Team1]],Countries[Country],Countries[FIFA Ranking],,0)>(_xlfn.XLOOKUP(Benchmark[[#This Row],[Team2]],Countries[Country],Countries[FIFA Ranking],,0))),1,0) -> 0 | G22: =Fixtures!E22 -> Congo DR | H22: =Fixtures!F22 -> Houston, NRG Stadium | J22: {=_xlfn.IFS(OR(ISBLANK('Results'!E22),ISBLANK('Results'!F22)),0,OR(ISBLANK(E22),ISBLANK(F22)),0,AND(E22='Results'!E22,F22='Results'!F22),Rules!$K$29,_xlfn.XOR(AND(E22>F22,'Results'!E22>'Results'!F22),AND(E22<F22,'Results'!E22<'Results'!F22),AND(E22=F22,'Results'!E22='Results'!F22)),Rules!$K$30,TRUE,0)} -> 0
A23: =Fixtures!A23 -> 22 | B23: =Fixtures!B23 -> 46190.833 | C23: =Fixtures!C23 -> Group L | D23: =Fixtures!D23 -> England | E23: =IF((_xlfn.XLOOKUP(Benchmark[[#This Row],[Team1]],Countries[Country],Countries[FIFA Ranking],,0)<(_xlfn.XLOOKUP(Benchmark[[#This Row],[Team2]],Countries[Country],Countries[FIFA Ranking],,0))),1,0) -> 1 | F23: =IF((_xlfn.XLOOKUP(Benchmark[[#This Row],[Team1]],Countries[Country],Countries[FIFA Ranking],,0)>(_xlfn.XLOOKUP(Benchmark[[#This Row],[Team2]],Countries[Country],Countries[FIFA Ranking],,0))),1,0) -> 0 | G23: =Fixtures!E23 -> Croatia | H23: =Fixtures!F23 -> Dallas, AT&T Stadium | J23: {=_xlfn.IFS(OR(ISBLANK('Results'!E23),ISBLANK('Results'!F23)),0,OR(ISBLANK(E23),ISBLANK(F23)),0,AND(E23='Results'!E23,F23='Results'!F23),Rules!$K$29,_xlfn.XOR(AND(E23>F23,'Results'!E23>'Results'!F23),AND(E23<F23,'Results'!E23<'Results'!F23),AND(E23=F23,'Results'!E23='Results'!F23)),Rules!$K$30,TRUE,0)} -> 0 | L23: Overall Winner
A24: =Fixtures!A24 -> 23 | B24: =Fixtures!B24 -> 46190.958 | C24: =Fixtures!C24 -> Group L | D24: =Fixtures!D24 -> Ghana | E24: =IF((_xlfn.XLOOKUP(Benchmark[[#This Row],[Team1]],Countries[Country],Countries[FIFA Ranking],,0)<(_xlfn.XLOOKUP(Benchmark[[#This Row],[Team2]],Countries[Country],Countries[FIFA Ranking],,0))),1,0) -> 0 | F24: =IF((_xlfn.XLOOKUP(Benchmark[[#This Row],[Team1]],Countries[Country],Countries[FIFA Ranking],,0)>(_xlfn.XLOOKUP(Benchmark[[#This Row],[Team2]],Countries[Country],Countries[FIFA Ranking],,0))),1,0) -> 1 | G24: =Fixtures!E24 -> Panama | H24: =Fixtures!F24 -> Toronto, BMO Field | J24: {=_xlfn.IFS(OR(ISBLANK('Results'!E24),ISBLANK('Results'!F24)),0,OR(ISBLANK(E24),ISBLANK(F24)),0,AND(E24='Results'!E24,F24='Results'!F24),Rules!$K$29,_xlfn.XOR(AND(E24>F24,'Results'!E24>'Results'!F24),AND(E24<F24,'Results'!E24<'Results'!F24),AND(E24=F24,'Results'!E24='Results'!F24)),Rules!$K$30,TRUE,0)} -> 0 | L24: =M20 -> Argentina | M24: {=INDEX(M10:M21,MATCH(MIN(INDEX(_xlfn.XLOOKUP(M10:M21,Countries[Country],Countries[FIFA Ranking]),)),INDEX(_xlfn.XLOOKUP(M10:M21,Countries[Country],Countries[FIFA Ranking]),),0))} -> #N/A | N24: {=_xlfn.IFS(OR(ISBLANK(M24),ISBLANK('Results'!K24)),0,M24='Results'!K24,Rules!$K$40,TRUE,0)} -> 0
A25: =Fixtures!A25 -> 24 | B25: =Fixtures!B25 -> 46191.083 | C25: =Fixtures!C25 -> Group K | D25: =Fixtures!D25 -> Uzbekistan | E25: =IF((_xlfn.XLOOKUP(Benchmark[[#This Row],[Team1]],Countries[Country],Countries[FIFA Ranking],,0)<(_xlfn.XLOOKUP(Benchmark[[#This Row],[Team2]],Countries[Country],Countries[FIFA Ranking],,0))),1,0) -> 0 | F25: =IF((_xlfn.XLOOKUP(Benchmark[[#This Row],[Team1]],Countries[Country],Countries[FIFA Ranking],,0)>(_xlfn.XLOOKUP(Benchmark[[#This Row],[Team2]],Countries[Country],Countries[FIFA Ranking],,0))),1,0) -> 1 | G25: =Fixtures!E25 -> Colombia | H25: =Fixtures!F25 -> Mexico City, Estadio Azteca | J25: {=_xlfn.IFS(OR(ISBLANK('Results'!E25),ISBLANK('Results'!F25)),0,OR(ISBLANK(E25),ISBLANK(F25)),0,AND(E25='Results'!E25,F25='Results'!F25),Rules!$K$29,_xlfn.XOR(AND(E25>F25,'Results'!E25>'Results'!F25),AND(E25<F25,'Results'!E25<'Results'!F25),AND(E25=F25,'Results'!E25='Results'!F25)),Rules!$K$30,TRUE,0)} -> 0
A26: =Fixtures!A26 -> 25 | B26: =Fixtures!B26 -> 46191.667 | C26: =Fixtures!C26 -> Group A | D26: =Fixtures!D26 -> Czechia | E26: =IF((_xlfn.XLOOKUP(Benchmark[[#This Row],[Team1]],Countries[Country],Countries[FIFA Ranking],,0)<(_xlfn.XLOOKUP(Benchmark[[#This Row],[Team2]],Countries[Country],Countries[FIFA Ranking],,0))),1,0) -> 1 | F26: =IF((_xlfn.XLOOKUP(Benchmark[[#This Row],[Team1]],Countries[Country],Countries[FIFA Ranking],,0)>(_xlfn.XLOOKUP(Benchmark[[#This Row],[Team2]],Countries[Country],Countries[FIFA Ranking],,0))),1,0) -> 0 | G26: =Fixtures!E26 -> South Africa | H26: =Fixtures!F26 -> Atlanta, Mercedes-Benz Stadium | J26: {=_xlfn.IFS(OR(ISBLANK('Results'!E26),ISBLANK('Results'!F26)),0,OR(ISBLANK(E26),ISBLANK(F26)),0,AND(E26='Results'!E26,F26='Results'!F26),Rules!$K$29,_xlfn.XOR(AND(E26>F26,'Results'!E26>'Results'!F26),AND(E26<F26,'Results'!E26<'Results'!F26),AND(E26=F26,'Results'!E26='Results'!F26)),Rules!$K$30,TRUE,0)} -> 0 | L26: Highest Goal Scoring Team
A27: =Fixtures!A27 -> 26 | B27: =Fixtures!B27 -> 46191.792 | C27: =Fixtures!C27 -> Group B | D27: =Fixtures!D27 -> Switzerland | E27: =IF((_xlfn.XLOOKUP(Benchmark[[#This Row],[Team1]],Countries[Country],Countries[FIFA Ranking],,0)<(_xlfn.XLOOKUP(Benchmark[[#This Row],[Team2]],Countries[Country],Countries[FIFA Ranking],,0))),1,0) -> 1 | F27: =IF((_xlfn.XLOOKUP(Benchmark[[#This Row],[Team1]],Countries[Country],Countries[FIFA Ranking],,0)>(_xlfn.XLOOKUP(Benchmark[[#This Row],[Team2]],Countries[Country],Countries[FIFA Ranking],,0))),1,0) -> 0 | G27: =Fixtures!E27 -> Bosnia and Herzegovina | H27: =Fixtures!F27 -> Los Angeles, SoFi Stadium | J27: {=_xlfn.IFS(OR(ISBLANK('Results'!E27),ISBLANK('Results'!F27)),0,OR(ISBLANK(E27),ISBLANK(F27)),0,AND(E27='Results'!E27,F27='Results'!F27),Rules!$K$29,_xlfn.XOR(AND(E27>F27,'Results'!E27>'Results'!F27),AND(E27<F27,'Results'!E27<'Results'!F27),AND(E27=F27,'Results'!E27='Results'!F27)),Rules!$K$30,TRUE,0)} -> 0 | L27: =M20 -> Argentina | N27: {=_xlfn.IFS(OR(ISBLANK(M27),ISBLANK('Results'!K27)),0,M27='Results'!K27,Rules!$K$41,TRUE,0)} -> 0
A28: =Fixtures!A28 -> 27 | B28: =Fixtures!B28 -> 46191.917 | C28: =Fixtures!C28 -> Group B | D28: =Fixtures!D28 -> Canada | E28: =IF((_xlfn.XLOOKUP(Benchmark[[#This Row],[Team1]],Countries[Country],Countries[FIFA Ranking],,0)<(_xlfn.XLOOKUP(Benchmark[[#This Row],[Team2]],Countries[Country],Countries[FIFA Ranking],,0))),1,0) -> 1 | F28: =IF((_xlfn.XLOOKUP(Benchmark[[#This Row],[Team1]],Countries[Country],Countries[FIFA Ranking],,0)>(_xlfn.XLOOKUP(Benchmark[[#This Row],[Team2]],Countries[Country],Countries[FIFA Ranking],,0))),1,0) -> 0 | G28: =Fixtures!E28 -> Qatar | H28: =Fixtures!F28 -> Vancouver, BC Place | J28: {=_xlfn.IFS(OR(ISBLANK('Results'!E28),ISBLANK('Results'!F28)),0,OR(ISBLANK(E28),ISBLANK(F28)),0,AND(E28='Results'!E28,F28='Results'!F28),Rules!$K$29,_xlfn.XOR(AND(E28>F28,'Results'!E28>'Results'!F28),AND(E28<F28,'Results'!E28<'Results'!F28),AND(E28=F28,'Results'!E28='Results'!F28)),Rules!$K$30,TRUE,0)} -> 0
A29: =Fixtures!A29 -> 28 | B29: =Fixtures!B29 -> 46192.042 | C29: =Fixtures!C29 -> Group A | D29: =Fixtures!D29 -> Mexico | E29: =IF((_xlfn.XLOOKUP(Benchmark[[#This Row],[Team1]],Countries[Country],Countries[FIFA Ranking],,0)<(_xlfn.XLOOKUP(Benchmark[[#This Row],[Team2]],Countries[Country],Countries[FIFA Ranking],,0))),1,0) -> 1 | F29: =IF((_xlfn.XLOOKUP(Benchmark[[#This Row],[Team1]],Countries[Country],Countries[FIFA Ranking],,0)>(_xlfn.XLOOKUP(Benchmark[[#This Row],[Team2]],Countries[Country],Countries[FIFA Ranking],,0))),1,0) -> 0 | G29: =Fixtures!E29 -> Korea Republic | H29: =Fixtures!F29 -> Guadalajara, Estadio Akron | J29: {=_xlfn.IFS(OR(ISBLANK('Results'!E29),ISBLANK('Results'!F29)),0,OR(ISBLANK(E29),ISBLANK(F29)),0,AND(E29='Results'!E29,F29='Results'!F29),Rules!$K$29,_xlfn.XOR(AND(E29>F29,'Results'!E29>'Results'!F29),AND(E29<F29,'Results'!E29<'Results'!F29),AND(E29=F29,'Results'!E29='Results'!F29)),Rules!$K$30,TRUE,0)} -> 0 | L29: Highest Goal Scorer
A30: =Fixtures!A30 -> 29 | B30: =Fixtures!B30 -> 46192.792 | C30: =Fixtures!C30 -> Group D | D30: =Fixtures!D30 -> USA | E30: =IF((_xlfn.XLOOKUP(Benchmark[[#This Row],[Team1]],Countries[Country],Countries[FIFA Ranking],,0)<(_xlfn.XLOOKUP(Benchmark[[#This Row],[Team2]],Countries[Country],Countries[FIFA Ranking],,0))),1,0) -> 1 | F30: =IF((_xlfn.XLOOKUP(Benchmark[[#This Row],[Team1]],Countries[Country],Countries[FIFA Ranking],,0)>(_xlfn.XLOOKUP(Benchmark[[#This Row],[Team2]],Countries[Country],Countries[FIFA Ranking],,0))),1,0) -> 0 | G30: =Fixtures!E30 -> Australia | H30: =Fixtures!F30 -> Seattle, Lumen Field | J30: {=_xlfn.IFS(OR(ISBLANK('Results'!E30),ISBLANK('Results'!F30)),0,OR(ISBLANK(E30),ISBLANK(F30)),0,AND(E30='Results'!E30,F30='Results'!F30),Rules!$K$29,_xlfn.XOR(AND(E30>F30,'Results'!E30>'Results'!F30),AND(E30<F30,'Results'!E30<'Results'!F30),AND(E30=F30,'Results'!E30='Results'!F30)),Rules!$K$30,TRUE,0)} -> 0 | L30: England | M30: =_xlfn.XLOOKUP(10,England[Shirt Number],England[Player Name],"Not Found") -> Jude Bellingham | N30: {=_xlfn.IFS(OR(ISBLANK(M30),ISBLANK('Results'!K30)),0,M30='Results'!K30,Rules!$K$43,TRUE,0)} -> 0
A31: =Fixtures!A31 -> 30 | B31: =Fixtures!B31 -> 46192.917 | C31: =Fixtures!C31 -> Group C | D31: =Fixtures!D31 -> Scotland | E31: =IF((_xlfn.XLOOKUP(Benchmark[[#This Row],[Team1]],Countries[Country],Countries[FIFA Ranking],,0)<(_xlfn.XLOOKUP(Benchmark[[#This Row],[Team2]],Countries[Country],Countries[FIFA Ranking],,0))),1,0) -> 0 | F31: =IF((_xlfn.XLOOKUP(Benchmark[[#This Row],[Team1]],Countries[Country],Countries[FIFA Ranking],,0)>(_xlfn.XLOOKUP(Benchmark[[#This Row],[Team2]],Countries[Country],Countries[FIFA Ranking],,0))),1,0) -> 1 | G31: =Fixtures!E31 -> Morocco | H31: =Fixtures!F31 -> Boston, Gillette Stadium | J31: {=_xlfn.IFS(OR(ISBLANK('Results'!E31),ISBLANK('Results'!F31)),0,OR(ISBLANK(E31),ISBLANK(F31)),0,AND(E31='Results'!E31,F31='Results'!F31),Rules!$K$29,_xlfn.XOR(AND(E31>F31,'Results'!E31>'Results'!F31),AND(E31<F31,'Results'!E31<'Results'!F31),AND(E31=F31,'Results'!E31='Results'!F31)),Rules!$K$30,TRUE,0)} -> 0
A32: =Fixtures!A32 -> 31 | B32: =Fixtures!B32 -> 46193.021 | C32: =Fixtures!C32 -> Group C | D32: =Fixtures!D32 -> Brazil | E32: =IF((_xlfn.XLOOKUP(Benchmark[[#This Row],[Team1]],Countries[Country],Countries[FIFA Ranking],,0)<(_xlfn.XLOOKUP(Benchmark[[#This Row],[Team2]],Countries[Country],Countries[FIFA Ranking],,0))),1,0) -> 1 | F32: =IF((_xlfn.XLOOKUP(Benchmark[[#This Row],[Team1]],Countries[Country],Countries[FIFA Ranking],,0)>(_xlfn.XLOOKUP(Benchmark[[#This Row],[Team2]],Countries[Country],Countries[FIFA Ranking],,0))),1,0) -> 0 | G32: =Fixtures!E32 -> Haiti | H32: =Fixtures!F32 -> Philadelphia, Lincoln Financial Field | J32: {=_xlfn.IFS(OR(ISBLANK('Results'!E32),ISBLANK('Results'!F32)),0,OR(ISBLANK(E32),ISBLANK(F32)),0,AND(E32='Results'!E32,F32='Results'!F32),Rules!$K$29,_xlfn.XOR(AND(E32>F32,'Results'!E32>'Results'!F32),AND(E32<F32,'Results'!E32<'Results'!F32),AND(E32=F32,'Results'!E32='Results'!F32)),Rules!$K$30,TRUE,0)} -> 0 | L32: Total Goals Conceded by
A33: =Fixtures!A33 -> 32 | B33: =Fixtures!B33 -> 46193.125 | C33: =Fixtures!C33 -> Group D | D33: =Fixtures!D33 -> Türkiye | E33: =IF((_xlfn.XLOOKUP(Benchmark[[#This Row],[Team1]],Countries[Country],Countries[FIFA Ranking],,0)<(_xlfn.XLOOKUP(Benchmark[[#This Row],[Team2]],Countries[Country],Countries[FIFA Ranking],,0))),1,0) -> 1 | F33: =IF((_xlfn.XLOOKUP(Benchmark[[#This Row],[Team1]],Countries[Country],Countries[FIFA Ranking],,0)>(_xlfn.XLOOKUP(Benchmark[[#This Row],[Team2]],Countries[Country],Countries[FIFA Ranking],,0))),1,0) -> 0 | G33: =Fixtures!E33 -> Paraguay | H33: =Fixtures!F33 -> San Francisco, Levi's Stadium | J33: {=_xlfn.IFS(OR(ISBLANK('Results'!E33),ISBLANK('Results'!F33)),0,OR(ISBLANK(E33),ISBLANK(F33)),0,AND(E33='Results'!E33,F33='Results'!F33),Rules!$K$29,_xlfn.XOR(AND(E33>F33,'Results'!E33>'Results'!F33),AND(E33<F33,'Results'!E33<'Results'!F33),AND(E33=F33,'Results'!E33='Results'!F33)),Rules!$K$30,TRUE,0)} -> 0 | L33: Canada | M33: 10 | N33: {=_xlfn.IFS(OR(ISBLANK(M33),ISBLANK('Results'!K33)),0,M33='Results'!K33,Rules!$K$45,TRUE,0)} -> 0
A34: =Fixtures!A34 -> 33 | B34: =Fixtures!B34 -> 46193.708 | C34: =Fixtures!C34 -> Group F | D34: =Fixtures!D34 -> Netherlands | E34: =IF((_xlfn.XLOOKUP(Benchmark[[#This Row],[Team1]],Countries[Country],Countries[FIFA Ranking],,0)<(_xlfn.XLOOKUP(Benchmark[[#This Row],[Team2]],Countries[Country],Countries[FIFA Ranking],,0))),1,0) -> 1 | F34: =IF((_xlfn.XLOOKUP(Benchmark[[#This Row],[Team1]],Countries[Country],Countries[FIFA Ranking],,0)>(_xlfn.XLOOKUP(Benchmark[[#This Row],[Team2]],Countries[Country],Countries[FIFA Ranking],,0))),1,0) -> 0 | G34: =Fixtures!E34 -> Sweden | H34: =Fixtures!F34 -> Houston, NRG Stadium | J34: {=_xlfn.IFS(OR(ISBLANK('Results'!E34),ISBLANK('Results'!F34)),0,OR(ISBLANK(E34),ISBLANK(F34)),0,AND(E34='Results'!E34,F34='Results'!F34),Rules!$K$29,_xlfn.XOR(AND(E34>F34,'Results'!E34>'Results'!F34),AND(E34<F34,'Results'!E34<'Results'!F34),AND(E34=F34,'Results'!E34='Results'!F34)),Rules!$K$30,TRUE,0)} -> 0 | L34: Mexico | M34: 10 | N34: {=_xlfn.IFS(OR(ISBLANK(M34),ISBLANK('Results'!K34)),0,M34='Results'!K34,Rules!$K$45,TRUE,0)} -> 0
A35: =Fixtures!A35 -> 34 | B35: =Fixtures!B35 -> 46193.833 | C35: =Fixtures!C35 -> Group E | D35: =Fixtures!D35 -> Germany | E35: =IF((_xlfn.XLOOKUP(Benchmark[[#This Row],[Team1]],Countries[Country],Countries[FIFA Ranking],,0)<(_xlfn.XLOOKUP(Benchmark[[#This Row],[Team2]],Countries[Country],Countries[FIFA Ranking],,0))),1,0) -> 1 | F35: =IF((_xlfn.XLOOKUP(Benchmark[[#This Row],[Team1]],Countries[Country],Countries[FIFA Ranking],,0)>(_xlfn.XLOOKUP(Benchmark[[#This Row],[Team2]],Countries[Country],Countries[FIFA Ranking],,0))),1,0) -> 0 | G35: =Fixtures!E35 -> Côte d'Ivoire | H35: =Fixtures!F35 -> Toronto, BMO Field | J35: {=_xlfn.IFS(OR(ISBLANK('Results'!E35),ISBLANK('Results'!F35)),0,OR(ISBLANK(E35),ISBLANK(F35)),0,AND(E35='Results'!E35,F35='Results'!F35),Rules!$K$29,_xlfn.XOR(AND(E35>F35,'Results'!E35>'Results'!F35),AND(E35<F35,'Results'!E35<'Results'!F35),AND(E35=F35,'Results'!E35='Results'!F35)),Rules!$K$30,TRUE,0)} -> 0 | L35: US | M35: 10 | N35: {=_xlfn.IFS(OR(ISBLANK(M35),ISBLANK('Results'!K35)),0,M35='Results'!K35,Rules!$K$45,TRUE,0)} -> 0
A36: =Fixtures!A36 -> 35 | B36: =Fixtures!B36 -> 46194 | C36: =Fixtures!C36 -> Group E | D36: =Fixtures!D36 -> Ecuador | E36: =IF((_xlfn.XLOOKUP(Benchmark[[#This Row],[Team1]],Countries[Country],Countries[FIFA Ranking],,0)<(_xlfn.XLOOKUP(Benchmark[[#This Row],[Team2]],Countries[Country],Countries[FIFA Ranking],,0))),1,0) -> 1 | F36: =IF((_xlfn.XLOOKUP(Benchmark[[#This Row],[Team1]],Countries[Country],Countries[FIFA Ranking],,0)>(_xlfn.XLOOKUP(Benchmark[[#This Row],[Team2]],Countries[Country],Countries[FIFA Ranking],,0))),1,0) -> 0 | G36: =Fixtures!E36 -> Curaçao | H36: =Fixtures!F36 -> Kansas City, Arrowhead Stadium | J36: {=_xlfn.IFS(OR(ISBLANK('Results'!E36),ISBLANK('Results'!F36)),0,OR(ISBLANK(E36),ISBLANK(F36)),0,AND(E36='Results'!E36,F36='Results'!F36),Rules!$K$29,_xlfn.XOR(AND(E36>F36,'Results'!E36>'Results'!F36),AND(E36<F36,'Results'!E36<'Results'!F36),AND(E36=F36,'Results'!E36='Results'!F36)),Rules!$K$30,TRUE,0)} -> 0
A37: =Fixtures!A37 -> 36 | B37: =Fixtures!B37 -> 46194.167 | C37: =Fixtures!C37 -> Group F | D37: =Fixtures!D37 -> Tunisia | E37: =IF((_xlfn.XLOOKUP(Benchmark[[#This Row],[Team1]],Countries[Country],Countries[FIFA Ranking],,0)<(_xlfn.XLOOKUP(Benchmark[[#This Row],[Team2]],Countries[Country],Countries[FIFA Ranking],,0))),1,0) -> 0 | F37: =IF((_xlfn.XLOOKUP(Benchmark[[#This Row],[Team1]],Countries[Country],Countries[FIFA Ranking],,0)>(_xlfn.XLOOKUP(Benchmark[[#This Row],[Team2]],Countries[Country],Countries[FIFA Ranking],,0))),1,0) -> 1 | G37: =Fixtures!E37 -> Japan | H37: =Fixtures!F37 -> Monterrey, Estadio BBVA | J37: {=_xlfn.IFS(OR(ISBLANK('Results'!E37),ISBLANK('Results'!F37)),0,OR(ISBLANK(E37),ISBLANK(F37)),0,AND(E37='Results'!E37,F37='Results'!F37),Rules!$K$29,_xlfn.XOR(AND(E37>F37,'Results'!E37>'Results'!F37),AND(E37<F37,'Results'!E37<'Results'!F37),AND(E37=F37,'Results'!E37='Results'!F37)),Rules!$K$30,TRUE,0)} -> 0
A38: =Fixtures!A38 -> 37 | B38: =Fixtures!B38 -> 46194.667 | C38: =Fixtures!C38 -> Group H | D38: =Fixtures!D38 -> Spain | E38: =IF((_xlfn.XLOOKUP(Benchmark[[#This Row],[Team1]],Countries[Country],Countries[FIFA Ranking],,0)<(_xlfn.XLOOKUP(Benchmark[[#This Row],[Team2]],Countries[Country],Countries[FIFA Ranking],,0))),1,0) -> 1 | F38: =IF((_xlfn.XLOOKUP(Benchmark[[#This Row],[Team1]],Countries[Country],Countries[FIFA Ranking],,0)>(_xlfn.XLOOKUP(Benchmark[[#This Row],[Team2]],Countries[Country],Countries[FIFA Ranking],,0))),1,0) -> 0 | G38: =Fixtures!E38 -> Saudi Arabia | H38: =Fixtures!F38 -> Atlanta, Mercedes-Benz Stadium | J38: {=_xlfn.IFS(OR(ISBLANK('Results'!E38),ISBLANK('Results'!F38)),0,OR(ISBLANK(E38),ISBLANK(F38)),0,AND(E38='Results'!E38,F38='Results'!F38),Rules!$K$29,_xlfn.XOR(AND(E38>F38,'Results'!E38>'Results'!F38),AND(E38<F38,'Results'!E38<'Results'!F38),AND(E38=F38,'Results'!E38='Results'!F38)),Rules!$K$30,TRUE,0)} -> 0
A39: =Fixtures!A39 -> 38 | B39: =Fixtures!B39 -> 46194.792 | C39: =Fixtures!C39 -> Group G | D39: =Fixtures!D39 -> Belgium | E39: =IF((_xlfn.XLOOKUP(Benchmark[[#This Row],[Team1]],Countries[Country],Countries[FIFA Ranking],,0)<(_xlfn.XLOOKUP(Benchmark[[#This Row],[Team2]],Countries[Country],Countries[FIFA Ranking],,0))),1,0) -> 1 | F39: =IF((_xlfn.XLOOKUP(Benchmark[[#This Row],[Team1]],Countries[Country],Countries[FIFA Ranking],,0)>(_xlfn.XLOOKUP(Benchmark[[#This Row],[Team2]],Countries[Country],Countries[FIFA Ranking],,0))),1,0) -> 0 | G39: =Fixtures!E39 -> IR Iran | H39: =Fixtures!F39 -> Los Angeles, SoFi Stadium | J39: {=_xlfn.IFS(OR(ISBLANK('Results'!E39),ISBLANK('Results'!F39)),0,OR(ISBLANK(E39),ISBLANK(F39)),0,AND(E39='Results'!E39,F39='Results'!F39),Rules!$K$29,_xlfn.XOR(AND(E39>F39,'Results'!E39>'Results'!F39),AND(E39<F39,'Results'!E39<'Results'!F39),AND(E39=F39,'Results'!E39='Results'!F39)),Rules!$K$30,TRUE,0)} -> 0
A40: =Fixtures!A40 -> 39 | B40: =Fixtures!B40 -> 46194.917 | C40: =Fixtures!C40 -> Group H | D40: =Fixtures!D40 -> Uruguay | E40: =IF((_xlfn.XLOOKUP(Benchmark[[#This Row],[Team1]],Countries[Country],Countries[FIFA Ranking],,0)<(_xlfn.XLOOKUP(Benchmark[[#This Row],[Team2]],Countries[Country],Countries[FIFA Ranking],,0))),1,0) -> 1 | F40: =IF((_xlfn.XLOOKUP(Benchmark[[#This Row],[Team1]],Countries[Country],Countries[FIFA Ranking],,0)>(_xlfn.XLOOKUP(Benchmark[[#This Row],[Team2]],Countries[Country],Countries[FIFA Ranking],,0))),1,0) -> 0 | G40: =Fixtures!E40 -> Cabo Verde | H40: =Fixtures!F40 -> Miami, Hard Rock Stadium | J40: {=_xlfn.IFS(OR(ISBLANK('Results'!E40),ISBLANK('Results'!F40)),0,OR(ISBLANK(E40),ISBLANK(F40)),0,AND(E40='Results'!E40,F40='Results'!F40),Rules!$K$29,_xlfn.XOR(AND(E40>F40,'Results'!E40>'Results'!F40),AND(E40<F40,'Results'!E40<'Results'!F40),AND(E40=F40,'Results'!E40='Results'!F40)),Rules!$K$30,TRUE,0)} -> 0
...

Sheet Demo
A1: GameID | B1: Date Time (GMT) | C1: Group/Stage | D1: Team1 | E1: Score1 | F1: Score2 | G1: Team2 | H1: Stadium | I1: Blank | J1: Points
A2: =Fixtures!A2 -> 1 | B2: =Fixtures!B2 -> 46184.792 | C2: =Fixtures!C2 -> Group A | D2: =Fixtures!D2 -> Mexico | G2: =Fixtures!E2 -> South Africa | H2: =Fixtures!F2 -> Mexico City, Estadio Azteca | J2: {=_xlfn.IFS(OR(ISBLANK('Results'!E2),ISBLANK('Results'!F2)),0,OR(ISBLANK(E2),ISBLANK(F2)),0,AND(E2='Results'!E2,F2='Results'!F2),Rules!$K$29,_xlfn.XOR(AND(E2>F2,'Results'!E2>'Results'!F2),AND(E2<F2,'Results'!E2<'Results'!F2),AND(E2=F2,'Results'!E2='Results'!F2)),Rules!$K$30,TRUE,0)} -> 0 | L2: Other Predictions
A3: =Fixtures!A3 -> 2 | B3: =Fixtures!B3 -> 46185.083 | C3: =Fixtures!C3 -> Group A | D3: =Fixtures!D3 -> Korea Republic | G3: =Fixtures!E3 -> Czechia | H3: =Fixtures!F3 -> Guadalajara, Estadio Akron | J3: {=_xlfn.IFS(OR(ISBLANK('Results'!E3),ISBLANK('Results'!F3)),0,OR(ISBLANK(E3),ISBLANK(F3)),0,AND(E3='Results'!E3,F3='Results'!F3),Rules!$K$29,_xlfn.XOR(AND(E3>F3,'Results'!E3>'Results'!F3),AND(E3<F3,'Results'!E3<'Results'!F3),AND(E3=F3,'Results'!E3='Results'!F3)),Rules!$K$30,TRUE,0)} -> 0 | N3: Points
A4: =Fixtures!A4 -> 3 | B4: =Fixtures!B4 -> 46185.792 | C4: =Fixtures!C4 -> Group B | D4: =Fixtures!D4 -> Canada | G4: =Fixtures!E4 -> Bosnia and Herzegovina | H4: =Fixtures!F4 -> Toronto, BMO Field | J4: {=_xlfn.IFS(OR(ISBLANK('Results'!E4),ISBLANK('Results'!F4)),0,OR(ISBLANK(E4),ISBLANK(F4)),0,AND(E4='Results'!E4,F4='Results'!F4),Rules!$K$29,_xlfn.XOR(AND(E4>F4,'Results'!E4>'Results'!F4),AND(E4<F4,'Results'!E4<'Results'!F4),AND(E4=F4,'Results'!E4='Results'!F4)),Rules!$K$30,TRUE,0)} -> 0 | L4: Group Stage Winners
A5: =Fixtures!A5 -> 4 | B5: =Fixtures!B5 -> 46186.042 | C5: =Fixtures!C5 -> Group D | D5: =Fixtures!D5 -> USA | G5: =Fixtures!E5 -> Paraguay | H5: =Fixtures!F5 -> Los Angeles, SoFi Stadium | J5: {=_xlfn.IFS(OR(ISBLANK('Results'!E5),ISBLANK('Results'!F5)),0,OR(ISBLANK(E5),ISBLANK(F5)),0,AND(E5='Results'!E5,F5='Results'!F5),Rules!$K$29,_xlfn.XOR(AND(E5>F5,'Results'!E5>'Results'!F5),AND(E5<F5,'Results'!E5<'Results'!F5),AND(E5=F5,'Results'!E5='Results'!F5)),Rules!$K$30,TRUE,0)} -> 0 | L5: Group | M5: Winner
A6: =Fixtures!A6 -> 5 | B6: =Fixtures!B6 -> 46186.792 | C6: =Fixtures!C6 -> Group B | D6: =Fixtures!D6 -> Qatar | G6: =Fixtures!E6 -> Switzerland | H6: =Fixtures!F6 -> San Francisco, Levi's Stadium | J6: {=_xlfn.IFS(OR(ISBLANK('Results'!E6),ISBLANK('Results'!F6)),0,OR(ISBLANK(E6),ISBLANK(F6)),0,AND(E6='Results'!E6,F6='Results'!F6),Rules!$K$29,_xlfn.XOR(AND(E6>F6,'Results'!E6>'Results'!F6),AND(E6<F6,'Results'!E6<'Results'!F6),AND(E6=F6,'Results'!E6='Results'!F6)),Rules!$K$30,TRUE,0)} -> 0 | L6: A | N6: {=_xlfn.IFS(OR(ISBLANK(M6),ISBLANK('Results'!K6)),0,M6='Results'!K6,Rules!$K$38,TRUE,0)} -> 0
A7: =Fixtures!A7 -> 6 | B7: =Fixtures!B7 -> 46186.917 | C7: =Fixtures!C7 -> Group C | D7: =Fixtures!D7 -> Brazil | G7: =Fixtures!E7 -> Morocco | H7: =Fixtures!F7 -> New York/New Jersey, MetLife Stadium | J7: {=_xlfn.IFS(OR(ISBLANK('Results'!E7),ISBLANK('Results'!F7)),0,OR(ISBLANK(E7),ISBLANK(F7)),0,AND(E7='Results'!E7,F7='Results'!F7),Rules!$K$29,_xlfn.XOR(AND(E7>F7,'Results'!E7>'Results'!F7),AND(E7<F7,'Results'!E7<'Results'!F7),AND(E7=F7,'Results'!E7='Results'!F7)),Rules!$K$30,TRUE,0)} -> 0 | L7: B | N7: {=_xlfn.IFS(OR(ISBLANK(M7),ISBLANK('Results'!K7)),0,M7='Results'!K7,Rules!$K$38,TRUE,0)} -> 0
